Traceback (most recent call last):
  File "/home/vitasoft/erpcons/passenger_wsgi.py", line 1, in <module>
    from erpcons.wsgi import application
  File "/home/vitasoft/erpcons/erpcons/wsgi.py", line 12, in <module>
    from django.core.wsgi import get_wsgi_application
ModuleNotFoundError: No module named 'django'
Traceback (most recent call last):
  File "/home/vitasoft/erpcons/passenger_wsgi.py", line 1, in <module>
    from erpcons.wsgi import application
  File "/home/vitasoft/erpcons/erpcons/wsgi.py", line 12, in <module>
    from django.core.wsgi import get_wsgi_application
ModuleNotFoundError: No module named 'django'
[UID:1210][1080895] Child process with pid: 1080906 was killed by signal: 15, core dumped: no
Traceback (most recent call last):
  File "/home/vitasoft/erpcons/passenger_wsgi.py", line 1, in <module>
    from erpcons.wsgi import application
  File "/home/vitasoft/erpcons/erpcons/wsgi.py", line 12, in <module>
    from django.core.wsgi import get_wsgi_application
ModuleNotFoundError: No module named 'django'
[UID:1210][1080895] Child process with pid: 1081912 was killed by signal: 15, core dumped: no
Not Found: /favicon.ico
Not Found: /favicon.ico
Internal Server Error: /admin/login/
Traceback (most recent call last):
  File "/home/vitasoft/virtualenv/erpcons/3.9/lib/python3.9/site-packages/django/db/backends/utils.py", line 89, in _execute
    return self.cursor.execute(sql, params)
  File "/home/vitasoft/virtualenv/erpcons/3.9/lib/python3.9/site-packages/django/db/backends/mysql/base.py", line 75, in execute
    return self.cursor.execute(query, args)
  File "/home/vitasoft/virtualenv/erpcons/3.9/lib/python3.9/site-packages/pymysql/cursors.py", line 153, in execute
    result = self._query(query)
  File "/home/vitasoft/virtualenv/erpcons/3.9/lib/python3.9/site-packages/pymysql/cursors.py", line 322, in _query
    conn.query(q)
  File "/home/vitasoft/virtualenv/erpcons/3.9/lib/python3.9/site-packages/pymysql/connections.py", line 558, in query
    self._affected_rows = self._read_query_result(unbuffered=unbuffered)
  File "/home/vitasoft/virtualenv/erpcons/3.9/lib/python3.9/site-packages/pymysql/connections.py", line 822, in _read_query_result
    result.read()
  File "/home/vitasoft/virtualenv/erpcons/3.9/lib/python3.9/site-packages/pymysql/connections.py", line 1200, in read
    first_packet = self.connection._read_packet()
  File "/home/vitasoft/virtualenv/erpcons/3.9/lib/python3.9/site-packages/pymysql/connections.py", line 772, in _read_packet
    packet.raise_for_error()
  File "/home/vitasoft/virtualenv/erpcons/3.9/lib/python3.9/site-packages/pymysql/protocol.py", line 221, in raise_for_error
    err.raise_mysql_exception(self._data)
  File "/home/vitasoft/virtualenv/erpcons/3.9/lib/python3.9/site-packages/pymysql/err.py", line 143, in raise_mysql_exception
    raise errorclass(errno, errval)
pymysql.err.ProgrammingError: (1146, "Table 'vitasoft_erpcons.users_employee' doesn't exist")

The above exception was the direct cause of the following exception:

Traceback (most recent call last):
  File "/home/vitasoft/virtualenv/erpcons/3.9/lib/python3.9/site-packages/django/core/handlers/exception.py", line 55, in inner
    response = get_response(request)
  File "/home/vitasoft/virtualenv/erpcons/3.9/lib/python3.9/site-packages/django/core/handlers/base.py", line 197, in _get_response
    response = wrapped_callback(request, *callback_args, **callback_kwargs)
  File "/home/vitasoft/virtualenv/erpcons/3.9/lib/python3.9/site-packages/django/utils/decorators.py", line 46, in _wrapper
    return bound_method(*args, **kwargs)
  File "/home/vitasoft/virtualenv/erpcons/3.9/lib/python3.9/site-packages/django/views/decorators/cache.py", line 62, in _wrapper_view_func
    response = view_func(request, *args, **kwargs)
  File "/home/vitasoft/virtualenv/erpcons/3.9/lib/python3.9/site-packages/django/contrib/admin/sites.py", line 441, in login
    return LoginView.as_view(**defaults)(request)
  File "/home/vitasoft/virtualenv/erpcons/3.9/lib/python3.9/site-packages/django/views/generic/base.py", line 104, in view
    return self.dispatch(request, *args, **kwargs)
  File "/home/vitasoft/virtualenv/erpcons/3.9/lib/python3.9/site-packages/django/utils/decorators.py", line 46, in _wrapper
    return bound_method(*args, **kwargs)
  File "/home/vitasoft/virtualenv/erpcons/3.9/lib/python3.9/site-packages/django/views/decorators/debug.py", line 92, in sensitive_post_parameters_wrapper
    return view(request, *args, **kwargs)
  File "/home/vitasoft/virtualenv/erpcons/3.9/lib/python3.9/site-packages/django/utils/decorators.py", line 46, in _wrapper
    return bound_method(*args, **kwargs)
  File "/home/vitasoft/virtualenv/erpcons/3.9/lib/python3.9/site-packages/django/utils/decorators.py", line 134, in _wrapper_view
    response = view_func(request, *args, **kwargs)
  File "/home/vitasoft/virtualenv/erpcons/3.9/lib/python3.9/site-packages/django/utils/decorators.py", line 46, in _wrapper
    return bound_method(*args, **kwargs)
  File "/home/vitasoft/virtualenv/erpcons/3.9/lib/python3.9/site-packages/django/views/decorators/cache.py", line 62, in _wrapper_view_func
    response = view_func(request, *args, **kwargs)
  File "/home/vitasoft/virtualenv/erpcons/3.9/lib/python3.9/site-packages/django/contrib/auth/views.py", line 90, in dispatch
    return super().dispatch(request, *args, **kwargs)
  File "/home/vitasoft/virtualenv/erpcons/3.9/lib/python3.9/site-packages/django/views/generic/base.py", line 143, in dispatch
    return handler(request, *args, **kwargs)
  File "/home/vitasoft/virtualenv/erpcons/3.9/lib/python3.9/site-packages/django/views/generic/edit.py", line 152, in post
    if form.is_valid():
  File "/home/vitasoft/virtualenv/erpcons/3.9/lib/python3.9/site-packages/django/forms/forms.py", line 201, in is_valid
    return self.is_bound and not self.errors
  File "/home/vitasoft/virtualenv/erpcons/3.9/lib/python3.9/site-packages/django/forms/forms.py", line 196, in errors
    self.full_clean()
  File "/home/vitasoft/virtualenv/erpcons/3.9/lib/python3.9/site-packages/django/forms/forms.py", line 434, in full_clean
    self._clean_form()
  File "/home/vitasoft/virtualenv/erpcons/3.9/lib/python3.9/site-packages/django/forms/forms.py", line 455, in _clean_form
    cleaned_data = self.clean()
  File "/home/vitasoft/virtualenv/erpcons/3.9/lib/python3.9/site-packages/django/contrib/auth/forms.py", line 242, in clean
    self.user_cache = authenticate(
  File "/home/vitasoft/virtualenv/erpcons/3.9/lib/python3.9/site-packages/django/views/decorators/debug.py", line 42, in sensitive_variables_wrapper
    return func(*func_args, **func_kwargs)
  File "/home/vitasoft/virtualenv/erpcons/3.9/lib/python3.9/site-packages/django/contrib/auth/__init__.py", line 77, in authenticate
    user = backend.authenticate(request, **credentials)
  File "/home/vitasoft/virtualenv/erpcons/3.9/lib/python3.9/site-packages/django/contrib/auth/backends.py", line 46, in authenticate
    user = UserModel._default_manager.get_by_natural_key(username)
  File "/home/vitasoft/virtualenv/erpcons/3.9/lib/python3.9/site-packages/django/contrib/auth/base_user.py", line 54, in get_by_natural_key
    return self.get(**{self.model.USERNAME_FIELD: username})
  File "/home/vitasoft/virtualenv/erpcons/3.9/lib/python3.9/site-packages/django/db/models/manager.py", line 87, in manager_method
    return getattr(self.get_queryset(), name)(*args, **kwargs)
  File "/home/vitasoft/virtualenv/erpcons/3.9/lib/python3.9/site-packages/django/db/models/query.py", line 633, in get
    num = len(clone)
  File "/home/vitasoft/virtualenv/erpcons/3.9/lib/python3.9/site-packages/django/db/models/query.py", line 380, in __len__
    self._fetch_all()
  File "/home/vitasoft/virtualenv/erpcons/3.9/lib/python3.9/site-packages/django/db/models/query.py", line 1881, in _fetch_all
    self._result_cache = list(self._iterable_class(self))
  File "/home/vitasoft/virtualenv/erpcons/3.9/lib/python3.9/site-packages/django/db/models/query.py", line 91, in __iter__
    results = compiler.execute_sql(
  File "/home/vitasoft/virtualenv/erpcons/3.9/lib/python3.9/site-packages/django/db/models/sql/compiler.py", line 1562, in execute_sql
    cursor.execute(sql, params)
  File "/home/vitasoft/virtualenv/erpcons/3.9/lib/python3.9/site-packages/django/db/backends/utils.py", line 102, in execute
    return super().execute(sql, params)
  File "/home/vitasoft/virtualenv/erpcons/3.9/lib/python3.9/site-packages/django/db/backends/utils.py", line 67, in execute
    return self._execute_with_wrappers(
  File "/home/vitasoft/virtualenv/erpcons/3.9/lib/python3.9/site-packages/django/db/backends/utils.py", line 80, in _execute_with_wrappers
    return executor(sql, params, many, context)
  File "/home/vitasoft/virtualenv/erpcons/3.9/lib/python3.9/site-packages/django/db/backends/utils.py", line 89, in _execute
    return self.cursor.execute(sql, params)
  File "/home/vitasoft/virtualenv/erpcons/3.9/lib/python3.9/site-packages/django/db/utils.py", line 91, in __exit__
    raise dj_exc_value.with_traceback(traceback) from exc_value
  File "/home/vitasoft/virtualenv/erpcons/3.9/lib/python3.9/site-packages/django/db/backends/utils.py", line 89, in _execute
    return self.cursor.execute(sql, params)
  File "/home/vitasoft/virtualenv/erpcons/3.9/lib/python3.9/site-packages/django/db/backends/mysql/base.py", line 75, in execute
    return self.cursor.execute(query, args)
  File "/home/vitasoft/virtualenv/erpcons/3.9/lib/python3.9/site-packages/pymysql/cursors.py", line 153, in execute
    result = self._query(query)
  File "/home/vitasoft/virtualenv/erpcons/3.9/lib/python3.9/site-packages/pymysql/cursors.py", line 322, in _query
    conn.query(q)
  File "/home/vitasoft/virtualenv/erpcons/3.9/lib/python3.9/site-packages/pymysql/connections.py", line 558, in query
    self._affected_rows = self._read_query_result(unbuffered=unbuffered)
  File "/home/vitasoft/virtualenv/erpcons/3.9/lib/python3.9/site-packages/pymysql/connections.py", line 822, in _read_query_result
    result.read()
  File "/home/vitasoft/virtualenv/erpcons/3.9/lib/python3.9/site-packages/pymysql/connections.py", line 1200, in read
    first_packet = self.connection._read_packet()
  File "/home/vitasoft/virtualenv/erpcons/3.9/lib/python3.9/site-packages/pymysql/connections.py", line 772, in _read_packet
    packet.raise_for_error()
  File "/home/vitasoft/virtualenv/erpcons/3.9/lib/python3.9/site-packages/pymysql/protocol.py", line 221, in raise_for_error
    err.raise_mysql_exception(self._data)
  File "/home/vitasoft/virtualenv/erpcons/3.9/lib/python3.9/site-packages/pymysql/err.py", line 143, in raise_mysql_exception
    raise errorclass(errno, errval)
django.db.utils.ProgrammingError: (1146, "Table 'vitasoft_erpcons.users_employee' doesn't exist")
Internal Server Error: /admin/login/
Traceback (most recent call last):
  File "/home/vitasoft/virtualenv/erpcons/3.9/lib/python3.9/site-packages/django/db/backends/utils.py", line 89, in _execute
    return self.cursor.execute(sql, params)
  File "/home/vitasoft/virtualenv/erpcons/3.9/lib/python3.9/site-packages/django/db/backends/mysql/base.py", line 75, in execute
    return self.cursor.execute(query, args)
  File "/home/vitasoft/virtualenv/erpcons/3.9/lib/python3.9/site-packages/pymysql/cursors.py", line 153, in execute
    result = self._query(query)
  File "/home/vitasoft/virtualenv/erpcons/3.9/lib/python3.9/site-packages/pymysql/cursors.py", line 322, in _query
    conn.query(q)
  File "/home/vitasoft/virtualenv/erpcons/3.9/lib/python3.9/site-packages/pymysql/connections.py", line 558, in query
    self._affected_rows = self._read_query_result(unbuffered=unbuffered)
  File "/home/vitasoft/virtualenv/erpcons/3.9/lib/python3.9/site-packages/pymysql/connections.py", line 822, in _read_query_result
    result.read()
  File "/home/vitasoft/virtualenv/erpcons/3.9/lib/python3.9/site-packages/pymysql/connections.py", line 1200, in read
    first_packet = self.connection._read_packet()
  File "/home/vitasoft/virtualenv/erpcons/3.9/lib/python3.9/site-packages/pymysql/connections.py", line 772, in _read_packet
    packet.raise_for_error()
  File "/home/vitasoft/virtualenv/erpcons/3.9/lib/python3.9/site-packages/pymysql/protocol.py", line 221, in raise_for_error
    err.raise_mysql_exception(self._data)
  File "/home/vitasoft/virtualenv/erpcons/3.9/lib/python3.9/site-packages/pymysql/err.py", line 143, in raise_mysql_exception
    raise errorclass(errno, errval)
pymysql.err.ProgrammingError: (1146, "Table 'vitasoft_erpcons.django_session' doesn't exist")

The above exception was the direct cause of the following exception:

Traceback (most recent call last):
  File "/home/vitasoft/virtualenv/erpcons/3.9/lib/python3.9/site-packages/django/core/handlers/exception.py", line 55, in inner
    response = get_response(request)
  File "/home/vitasoft/virtualenv/erpcons/3.9/lib/python3.9/site-packages/django/core/handlers/base.py", line 197, in _get_response
    response = wrapped_callback(request, *callback_args, **callback_kwargs)
  File "/home/vitasoft/virtualenv/erpcons/3.9/lib/python3.9/site-packages/django/utils/decorators.py", line 46, in _wrapper
    return bound_method(*args, **kwargs)
  File "/home/vitasoft/virtualenv/erpcons/3.9/lib/python3.9/site-packages/django/views/decorators/cache.py", line 62, in _wrapper_view_func
    response = view_func(request, *args, **kwargs)
  File "/home/vitasoft/virtualenv/erpcons/3.9/lib/python3.9/site-packages/django/contrib/admin/sites.py", line 441, in login
    return LoginView.as_view(**defaults)(request)
  File "/home/vitasoft/virtualenv/erpcons/3.9/lib/python3.9/site-packages/django/views/generic/base.py", line 104, in view
    return self.dispatch(request, *args, **kwargs)
  File "/home/vitasoft/virtualenv/erpcons/3.9/lib/python3.9/site-packages/django/utils/decorators.py", line 46, in _wrapper
    return bound_method(*args, **kwargs)
  File "/home/vitasoft/virtualenv/erpcons/3.9/lib/python3.9/site-packages/django/views/decorators/debug.py", line 92, in sensitive_post_parameters_wrapper
    return view(request, *args, **kwargs)
  File "/home/vitasoft/virtualenv/erpcons/3.9/lib/python3.9/site-packages/django/utils/decorators.py", line 46, in _wrapper
    return bound_method(*args, **kwargs)
  File "/home/vitasoft/virtualenv/erpcons/3.9/lib/python3.9/site-packages/django/utils/decorators.py", line 134, in _wrapper_view
    response = view_func(request, *args, **kwargs)
  File "/home/vitasoft/virtualenv/erpcons/3.9/lib/python3.9/site-packages/django/utils/decorators.py", line 46, in _wrapper
    return bound_method(*args, **kwargs)
  File "/home/vitasoft/virtualenv/erpcons/3.9/lib/python3.9/site-packages/django/views/decorators/cache.py", line 62, in _wrapper_view_func
    response = view_func(request, *args, **kwargs)
  File "/home/vitasoft/virtualenv/erpcons/3.9/lib/python3.9/site-packages/django/contrib/auth/views.py", line 90, in dispatch
    return super().dispatch(request, *args, **kwargs)
  File "/home/vitasoft/virtualenv/erpcons/3.9/lib/python3.9/site-packages/django/views/generic/base.py", line 143, in dispatch
    return handler(request, *args, **kwargs)
  File "/home/vitasoft/virtualenv/erpcons/3.9/lib/python3.9/site-packages/django/views/generic/edit.py", line 153, in post
    return self.form_valid(form)
  File "/home/vitasoft/virtualenv/erpcons/3.9/lib/python3.9/site-packages/django/contrib/auth/views.py", line 109, in form_valid
    auth_login(self.request, form.get_user())
  File "/home/vitasoft/virtualenv/erpcons/3.9/lib/python3.9/site-packages/django/contrib/auth/__init__.py", line 118, in login
    request.session.cycle_key()
  File "/home/vitasoft/virtualenv/erpcons/3.9/lib/python3.9/site-packages/django/contrib/sessions/backends/base.py", line 304, in cycle_key
    self.create()
  File "/home/vitasoft/virtualenv/erpcons/3.9/lib/python3.9/site-packages/django/contrib/sessions/backends/db.py", line 50, in create
    self._session_key = self._get_new_session_key()
  File "/home/vitasoft/virtualenv/erpcons/3.9/lib/python3.9/site-packages/django/contrib/sessions/backends/base.py", line 150, in _get_new_session_key
    if not self.exists(session_key):
  File "/home/vitasoft/virtualenv/erpcons/3.9/lib/python3.9/site-packages/django/contrib/sessions/backends/db.py", line 46, in exists
    return self.model.objects.filter(session_key=session_key).exists()
  File "/home/vitasoft/virtualenv/erpcons/3.9/lib/python3.9/site-packages/django/db/models/query.py", line 1241, in exists
    return self.query.has_results(using=self.db)
  File "/home/vitasoft/virtualenv/erpcons/3.9/lib/python3.9/site-packages/django/db/models/sql/query.py", line 587, in has_results
    return compiler.has_results()
  File "/home/vitasoft/virtualenv/erpcons/3.9/lib/python3.9/site-packages/django/db/models/sql/compiler.py", line 1530, in has_results
    return bool(self.execute_sql(SINGLE))
  File "/home/vitasoft/virtualenv/erpcons/3.9/lib/python3.9/site-packages/django/db/models/sql/compiler.py", line 1562, in execute_sql
    cursor.execute(sql, params)
  File "/home/vitasoft/virtualenv/erpcons/3.9/lib/python3.9/site-packages/django/db/backends/utils.py", line 102, in execute
    return super().execute(sql, params)
  File "/home/vitasoft/virtualenv/erpcons/3.9/lib/python3.9/site-packages/django/db/backends/utils.py", line 67, in execute
    return self._execute_with_wrappers(
  File "/home/vitasoft/virtualenv/erpcons/3.9/lib/python3.9/site-packages/django/db/backends/utils.py", line 80, in _execute_with_wrappers
    return executor(sql, params, many, context)
  File "/home/vitasoft/virtualenv/erpcons/3.9/lib/python3.9/site-packages/django/db/backends/utils.py", line 89, in _execute
    return self.cursor.execute(sql, params)
  File "/home/vitasoft/virtualenv/erpcons/3.9/lib/python3.9/site-packages/django/db/utils.py", line 91, in __exit__
    raise dj_exc_value.with_traceback(traceback) from exc_value
  File "/home/vitasoft/virtualenv/erpcons/3.9/lib/python3.9/site-packages/django/db/backends/utils.py", line 89, in _execute
    return self.cursor.execute(sql, params)
  File "/home/vitasoft/virtualenv/erpcons/3.9/lib/python3.9/site-packages/django/db/backends/mysql/base.py", line 75, in execute
    return self.cursor.execute(query, args)
  File "/home/vitasoft/virtualenv/erpcons/3.9/lib/python3.9/site-packages/pymysql/cursors.py", line 153, in execute
    result = self._query(query)
  File "/home/vitasoft/virtualenv/erpcons/3.9/lib/python3.9/site-packages/pymysql/cursors.py", line 322, in _query
    conn.query(q)
  File "/home/vitasoft/virtualenv/erpcons/3.9/lib/python3.9/site-packages/pymysql/connections.py", line 558, in query
    self._affected_rows = self._read_query_result(unbuffered=unbuffered)
  File "/home/vitasoft/virtualenv/erpcons/3.9/lib/python3.9/site-packages/pymysql/connections.py", line 822, in _read_query_result
    result.read()
  File "/home/vitasoft/virtualenv/erpcons/3.9/lib/python3.9/site-packages/pymysql/connections.py", line 1200, in read
    first_packet = self.connection._read_packet()
  File "/home/vitasoft/virtualenv/erpcons/3.9/lib/python3.9/site-packages/pymysql/connections.py", line 772, in _read_packet
    packet.raise_for_error()
  File "/home/vitasoft/virtualenv/erpcons/3.9/lib/python3.9/site-packages/pymysql/protocol.py", line 221, in raise_for_error
    err.raise_mysql_exception(self._data)
  File "/home/vitasoft/virtualenv/erpcons/3.9/lib/python3.9/site-packages/pymysql/err.py", line 143, in raise_mysql_exception
    raise errorclass(errno, errval)
django.db.utils.ProgrammingError: (1146, "Table 'vitasoft_erpcons.django_session' doesn't exist")
Invalid HTTP_HOST header: 'www.erpcons.vitasoftsolutions.com'. You may need to add 'www.erpcons.vitasoftsolutions.com' to ALLOWED_HOSTS.
Traceback (most recent call last):
  File "/home/vitasoft/virtualenv/erpcons/3.9/lib/python3.9/site-packages/django/core/handlers/exception.py", line 55, in inner
    response = get_response(request)
  File "/home/vitasoft/virtualenv/erpcons/3.9/lib/python3.9/site-packages/django/utils/deprecation.py", line 133, in __call__
    response = self.process_request(request)
  File "/home/vitasoft/virtualenv/erpcons/3.9/lib/python3.9/site-packages/django/middleware/common.py", line 48, in process_request
    host = request.get_host()
  File "/home/vitasoft/virtualenv/erpcons/3.9/lib/python3.9/site-packages/django/http/request.py", line 150, in get_host
    raise DisallowedHost(msg)
django.core.exceptions.DisallowedHost: Invalid HTTP_HOST header: 'www.erpcons.vitasoftsolutions.com'. You may need to add 'www.erpcons.vitasoftsolutions.com' to ALLOWED_HOSTS.
Bad Request: /
Internal Server Error: /admin/contructors/contractorgarrentor/
Traceback (most recent call last):
  File "/home/vitasoft/virtualenv/erpcons/3.9/lib/python3.9/site-packages/django/db/backends/utils.py", line 89, in _execute
    return self.cursor.execute(sql, params)
  File "/home/vitasoft/virtualenv/erpcons/3.9/lib/python3.9/site-packages/django/db/backends/mysql/base.py", line 75, in execute
    return self.cursor.execute(query, args)
  File "/home/vitasoft/virtualenv/erpcons/3.9/lib/python3.9/site-packages/pymysql/cursors.py", line 153, in execute
    result = self._query(query)
  File "/home/vitasoft/virtualenv/erpcons/3.9/lib/python3.9/site-packages/pymysql/cursors.py", line 322, in _query
    conn.query(q)
  File "/home/vitasoft/virtualenv/erpcons/3.9/lib/python3.9/site-packages/pymysql/connections.py", line 558, in query
    self._affected_rows = self._read_query_result(unbuffered=unbuffered)
  File "/home/vitasoft/virtualenv/erpcons/3.9/lib/python3.9/site-packages/pymysql/connections.py", line 822, in _read_query_result
    result.read()
  File "/home/vitasoft/virtualenv/erpcons/3.9/lib/python3.9/site-packages/pymysql/connections.py", line 1200, in read
    first_packet = self.connection._read_packet()
  File "/home/vitasoft/virtualenv/erpcons/3.9/lib/python3.9/site-packages/pymysql/connections.py", line 772, in _read_packet
    packet.raise_for_error()
  File "/home/vitasoft/virtualenv/erpcons/3.9/lib/python3.9/site-packages/pymysql/protocol.py", line 221, in raise_for_error
    err.raise_mysql_exception(self._data)
  File "/home/vitasoft/virtualenv/erpcons/3.9/lib/python3.9/site-packages/pymysql/err.py", line 143, in raise_mysql_exception
    raise errorclass(errno, errval)
pymysql.err.OperationalError: (1054, "Unknown column 'globalapp2_introinfo.author_id_id' in 'field list'")

The above exception was the direct cause of the following exception:

Traceback (most recent call last):
  File "/home/vitasoft/virtualenv/erpcons/3.9/lib/python3.9/site-packages/django/core/handlers/exception.py", line 55, in inner
    response = get_response(request)
  File "/home/vitasoft/virtualenv/erpcons/3.9/lib/python3.9/site-packages/django/core/handlers/base.py", line 197, in _get_response
    response = wrapped_callback(request, *callback_args, **callback_kwargs)
  File "/home/vitasoft/virtualenv/erpcons/3.9/lib/python3.9/site-packages/django/contrib/admin/options.py", line 688, in wrapper
    return self.admin_site.admin_view(view)(*args, **kwargs)
  File "/home/vitasoft/virtualenv/erpcons/3.9/lib/python3.9/site-packages/django/utils/decorators.py", line 134, in _wrapper_view
    response = view_func(request, *args, **kwargs)
  File "/home/vitasoft/virtualenv/erpcons/3.9/lib/python3.9/site-packages/django/views/decorators/cache.py", line 62, in _wrapper_view_func
    response = view_func(request, *args, **kwargs)
  File "/home/vitasoft/virtualenv/erpcons/3.9/lib/python3.9/site-packages/django/contrib/admin/sites.py", line 242, in inner
    return view(request, *args, **kwargs)
  File "/home/vitasoft/virtualenv/erpcons/3.9/lib/python3.9/site-packages/django/utils/decorators.py", line 46, in _wrapper
    return bound_method(*args, **kwargs)
  File "/home/vitasoft/virtualenv/erpcons/3.9/lib/python3.9/site-packages/django/utils/decorators.py", line 134, in _wrapper_view
    response = view_func(request, *args, **kwargs)
  File "/home/vitasoft/virtualenv/erpcons/3.9/lib/python3.9/site-packages/django/contrib/admin/options.py", line 2065, in changelist_view
    "selection_note": _("0 of %(cnt)s selected") % {"cnt": len(cl.result_list)},
  File "/home/vitasoft/virtualenv/erpcons/3.9/lib/python3.9/site-packages/django/db/models/query.py", line 380, in __len__
    self._fetch_all()
  File "/home/vitasoft/virtualenv/erpcons/3.9/lib/python3.9/site-packages/django/db/models/query.py", line 1881, in _fetch_all
    self._result_cache = list(self._iterable_class(self))
  File "/home/vitasoft/virtualenv/erpcons/3.9/lib/python3.9/site-packages/django/db/models/query.py", line 91, in __iter__
    results = compiler.execute_sql(
  File "/home/vitasoft/virtualenv/erpcons/3.9/lib/python3.9/site-packages/django/db/models/sql/compiler.py", line 1562, in execute_sql
    cursor.execute(sql, params)
  File "/home/vitasoft/virtualenv/erpcons/3.9/lib/python3.9/site-packages/django/db/backends/utils.py", line 102, in execute
    return super().execute(sql, params)
  File "/home/vitasoft/virtualenv/erpcons/3.9/lib/python3.9/site-packages/django/db/backends/utils.py", line 67, in execute
    return self._execute_with_wrappers(
  File "/home/vitasoft/virtualenv/erpcons/3.9/lib/python3.9/site-packages/django/db/backends/utils.py", line 80, in _execute_with_wrappers
    return executor(sql, params, many, context)
  File "/home/vitasoft/virtualenv/erpcons/3.9/lib/python3.9/site-packages/django/db/backends/utils.py", line 89, in _execute
    return self.cursor.execute(sql, params)
  File "/home/vitasoft/virtualenv/erpcons/3.9/lib/python3.9/site-packages/django/db/utils.py", line 91, in __exit__
    raise dj_exc_value.with_traceback(traceback) from exc_value
  File "/home/vitasoft/virtualenv/erpcons/3.9/lib/python3.9/site-packages/django/db/backends/utils.py", line 89, in _execute
    return self.cursor.execute(sql, params)
  File "/home/vitasoft/virtualenv/erpcons/3.9/lib/python3.9/site-packages/django/db/backends/mysql/base.py", line 75, in execute
    return self.cursor.execute(query, args)
  File "/home/vitasoft/virtualenv/erpcons/3.9/lib/python3.9/site-packages/pymysql/cursors.py", line 153, in execute
    result = self._query(query)
  File "/home/vitasoft/virtualenv/erpcons/3.9/lib/python3.9/site-packages/pymysql/cursors.py", line 322, in _query
    conn.query(q)
  File "/home/vitasoft/virtualenv/erpcons/3.9/lib/python3.9/site-packages/pymysql/connections.py", line 558, in query
    self._affected_rows = self._read_query_result(unbuffered=unbuffered)
  File "/home/vitasoft/virtualenv/erpcons/3.9/lib/python3.9/site-packages/pymysql/connections.py", line 822, in _read_query_result
    result.read()
  File "/home/vitasoft/virtualenv/erpcons/3.9/lib/python3.9/site-packages/pymysql/connections.py", line 1200, in read
    first_packet = self.connection._read_packet()
  File "/home/vitasoft/virtualenv/erpcons/3.9/lib/python3.9/site-packages/pymysql/connections.py", line 772, in _read_packet
    packet.raise_for_error()
  File "/home/vitasoft/virtualenv/erpcons/3.9/lib/python3.9/site-packages/pymysql/protocol.py", line 221, in raise_for_error
    err.raise_mysql_exception(self._data)
  File "/home/vitasoft/virtualenv/erpcons/3.9/lib/python3.9/site-packages/pymysql/err.py", line 143, in raise_mysql_exception
    raise errorclass(errno, errval)
django.db.utils.OperationalError: (1054, "Unknown column 'globalapp2_introinfo.author_id_id' in 'field list'")
Internal Server Error: /admin/customers/customerbeneficaries/
Traceback (most recent call last):
  File "/home/vitasoft/virtualenv/erpcons/3.9/lib/python3.9/site-packages/django/db/backends/utils.py", line 89, in _execute
    return self.cursor.execute(sql, params)
  File "/home/vitasoft/virtualenv/erpcons/3.9/lib/python3.9/site-packages/django/db/backends/mysql/base.py", line 75, in execute
    return self.cursor.execute(query, args)
  File "/home/vitasoft/virtualenv/erpcons/3.9/lib/python3.9/site-packages/pymysql/cursors.py", line 153, in execute
    result = self._query(query)
  File "/home/vitasoft/virtualenv/erpcons/3.9/lib/python3.9/site-packages/pymysql/cursors.py", line 322, in _query
    conn.query(q)
  File "/home/vitasoft/virtualenv/erpcons/3.9/lib/python3.9/site-packages/pymysql/connections.py", line 558, in query
    self._affected_rows = self._read_query_result(unbuffered=unbuffered)
  File "/home/vitasoft/virtualenv/erpcons/3.9/lib/python3.9/site-packages/pymysql/connections.py", line 822, in _read_query_result
    result.read()
  File "/home/vitasoft/virtualenv/erpcons/3.9/lib/python3.9/site-packages/pymysql/connections.py", line 1200, in read
    first_packet = self.connection._read_packet()
  File "/home/vitasoft/virtualenv/erpcons/3.9/lib/python3.9/site-packages/pymysql/connections.py", line 772, in _read_packet
    packet.raise_for_error()
  File "/home/vitasoft/virtualenv/erpcons/3.9/lib/python3.9/site-packages/pymysql/protocol.py", line 221, in raise_for_error
    err.raise_mysql_exception(self._data)
  File "/home/vitasoft/virtualenv/erpcons/3.9/lib/python3.9/site-packages/pymysql/err.py", line 143, in raise_mysql_exception
    raise errorclass(errno, errval)
pymysql.err.OperationalError: (1054, "Unknown column 'globalapp2_introinfo.author_id_id' in 'field list'")

The above exception was the direct cause of the following exception:

Traceback (most recent call last):
  File "/home/vitasoft/virtualenv/erpcons/3.9/lib/python3.9/site-packages/django/core/handlers/exception.py", line 55, in inner
    response = get_response(request)
  File "/home/vitasoft/virtualenv/erpcons/3.9/lib/python3.9/site-packages/django/core/handlers/base.py", line 197, in _get_response
    response = wrapped_callback(request, *callback_args, **callback_kwargs)
  File "/home/vitasoft/virtualenv/erpcons/3.9/lib/python3.9/site-packages/django/contrib/admin/options.py", line 688, in wrapper
    return self.admin_site.admin_view(view)(*args, **kwargs)
  File "/home/vitasoft/virtualenv/erpcons/3.9/lib/python3.9/site-packages/django/utils/decorators.py", line 134, in _wrapper_view
    response = view_func(request, *args, **kwargs)
  File "/home/vitasoft/virtualenv/erpcons/3.9/lib/python3.9/site-packages/django/views/decorators/cache.py", line 62, in _wrapper_view_func
    response = view_func(request, *args, **kwargs)
  File "/home/vitasoft/virtualenv/erpcons/3.9/lib/python3.9/site-packages/django/contrib/admin/sites.py", line 242, in inner
    return view(request, *args, **kwargs)
  File "/home/vitasoft/virtualenv/erpcons/3.9/lib/python3.9/site-packages/django/utils/decorators.py", line 46, in _wrapper
    return bound_method(*args, **kwargs)
  File "/home/vitasoft/virtualenv/erpcons/3.9/lib/python3.9/site-packages/django/utils/decorators.py", line 134, in _wrapper_view
    response = view_func(request, *args, **kwargs)
  File "/home/vitasoft/virtualenv/erpcons/3.9/lib/python3.9/site-packages/django/contrib/admin/options.py", line 2065, in changelist_view
    "selection_note": _("0 of %(cnt)s selected") % {"cnt": len(cl.result_list)},
  File "/home/vitasoft/virtualenv/erpcons/3.9/lib/python3.9/site-packages/django/db/models/query.py", line 380, in __len__
    self._fetch_all()
  File "/home/vitasoft/virtualenv/erpcons/3.9/lib/python3.9/site-packages/django/db/models/query.py", line 1881, in _fetch_all
    self._result_cache = list(self._iterable_class(self))
  File "/home/vitasoft/virtualenv/erpcons/3.9/lib/python3.9/site-packages/django/db/models/query.py", line 91, in __iter__
    results = compiler.execute_sql(
  File "/home/vitasoft/virtualenv/erpcons/3.9/lib/python3.9/site-packages/django/db/models/sql/compiler.py", line 1562, in execute_sql
    cursor.execute(sql, params)
  File "/home/vitasoft/virtualenv/erpcons/3.9/lib/python3.9/site-packages/django/db/backends/utils.py", line 102, in execute
    return super().execute(sql, params)
  File "/home/vitasoft/virtualenv/erpcons/3.9/lib/python3.9/site-packages/django/db/backends/utils.py", line 67, in execute
    return self._execute_with_wrappers(
  File "/home/vitasoft/virtualenv/erpcons/3.9/lib/python3.9/site-packages/django/db/backends/utils.py", line 80, in _execute_with_wrappers
    return executor(sql, params, many, context)
  File "/home/vitasoft/virtualenv/erpcons/3.9/lib/python3.9/site-packages/django/db/backends/utils.py", line 89, in _execute
    return self.cursor.execute(sql, params)
  File "/home/vitasoft/virtualenv/erpcons/3.9/lib/python3.9/site-packages/django/db/utils.py", line 91, in __exit__
    raise dj_exc_value.with_traceback(traceback) from exc_value
  File "/home/vitasoft/virtualenv/erpcons/3.9/lib/python3.9/site-packages/django/db/backends/utils.py", line 89, in _execute
    return self.cursor.execute(sql, params)
  File "/home/vitasoft/virtualenv/erpcons/3.9/lib/python3.9/site-packages/django/db/backends/mysql/base.py", line 75, in execute
    return self.cursor.execute(query, args)
  File "/home/vitasoft/virtualenv/erpcons/3.9/lib/python3.9/site-packages/pymysql/cursors.py", line 153, in execute
    result = self._query(query)
  File "/home/vitasoft/virtualenv/erpcons/3.9/lib/python3.9/site-packages/pymysql/cursors.py", line 322, in _query
    conn.query(q)
  File "/home/vitasoft/virtualenv/erpcons/3.9/lib/python3.9/site-packages/pymysql/connections.py", line 558, in query
    self._affected_rows = self._read_query_result(unbuffered=unbuffered)
  File "/home/vitasoft/virtualenv/erpcons/3.9/lib/python3.9/site-packages/pymysql/connections.py", line 822, in _read_query_result
    result.read()
  File "/home/vitasoft/virtualenv/erpcons/3.9/lib/python3.9/site-packages/pymysql/connections.py", line 1200, in read
    first_packet = self.connection._read_packet()
  File "/home/vitasoft/virtualenv/erpcons/3.9/lib/python3.9/site-packages/pymysql/connections.py", line 772, in _read_packet
    packet.raise_for_error()
  File "/home/vitasoft/virtualenv/erpcons/3.9/lib/python3.9/site-packages/pymysql/protocol.py", line 221, in raise_for_error
    err.raise_mysql_exception(self._data)
  File "/home/vitasoft/virtualenv/erpcons/3.9/lib/python3.9/site-packages/pymysql/err.py", line 143, in raise_mysql_exception
    raise errorclass(errno, errval)
django.db.utils.OperationalError: (1054, "Unknown column 'globalapp2_introinfo.author_id_id' in 'field list'")
Internal Server Error: /admin/owner/ownerbeneficaries/
Traceback (most recent call last):
  File "/home/vitasoft/virtualenv/erpcons/3.9/lib/python3.9/site-packages/django/db/backends/utils.py", line 89, in _execute
    return self.cursor.execute(sql, params)
  File "/home/vitasoft/virtualenv/erpcons/3.9/lib/python3.9/site-packages/django/db/backends/mysql/base.py", line 75, in execute
    return self.cursor.execute(query, args)
  File "/home/vitasoft/virtualenv/erpcons/3.9/lib/python3.9/site-packages/pymysql/cursors.py", line 153, in execute
    result = self._query(query)
  File "/home/vitasoft/virtualenv/erpcons/3.9/lib/python3.9/site-packages/pymysql/cursors.py", line 322, in _query
    conn.query(q)
  File "/home/vitasoft/virtualenv/erpcons/3.9/lib/python3.9/site-packages/pymysql/connections.py", line 558, in query
    self._affected_rows = self._read_query_result(unbuffered=unbuffered)
  File "/home/vitasoft/virtualenv/erpcons/3.9/lib/python3.9/site-packages/pymysql/connections.py", line 822, in _read_query_result
    result.read()
  File "/home/vitasoft/virtualenv/erpcons/3.9/lib/python3.9/site-packages/pymysql/connections.py", line 1200, in read
    first_packet = self.connection._read_packet()
  File "/home/vitasoft/virtualenv/erpcons/3.9/lib/python3.9/site-packages/pymysql/connections.py", line 772, in _read_packet
    packet.raise_for_error()
  File "/home/vitasoft/virtualenv/erpcons/3.9/lib/python3.9/site-packages/pymysql/protocol.py", line 221, in raise_for_error
    err.raise_mysql_exception(self._data)
  File "/home/vitasoft/virtualenv/erpcons/3.9/lib/python3.9/site-packages/pymysql/err.py", line 143, in raise_mysql_exception
    raise errorclass(errno, errval)
pymysql.err.ProgrammingError: (1146, "Table 'vitasoft_erpcons.owner_ownerbeneficaries' doesn't exist")

The above exception was the direct cause of the following exception:

Traceback (most recent call last):
  File "/home/vitasoft/virtualenv/erpcons/3.9/lib/python3.9/site-packages/django/core/handlers/exception.py", line 55, in inner
    response = get_response(request)
  File "/home/vitasoft/virtualenv/erpcons/3.9/lib/python3.9/site-packages/django/core/handlers/base.py", line 197, in _get_response
    response = wrapped_callback(request, *callback_args, **callback_kwargs)
  File "/home/vitasoft/virtualenv/erpcons/3.9/lib/python3.9/site-packages/django/contrib/admin/options.py", line 688, in wrapper
    return self.admin_site.admin_view(view)(*args, **kwargs)
  File "/home/vitasoft/virtualenv/erpcons/3.9/lib/python3.9/site-packages/django/utils/decorators.py", line 134, in _wrapper_view
    response = view_func(request, *args, **kwargs)
  File "/home/vitasoft/virtualenv/erpcons/3.9/lib/python3.9/site-packages/django/views/decorators/cache.py", line 62, in _wrapper_view_func
    response = view_func(request, *args, **kwargs)
  File "/home/vitasoft/virtualenv/erpcons/3.9/lib/python3.9/site-packages/django/contrib/admin/sites.py", line 242, in inner
    return view(request, *args, **kwargs)
  File "/home/vitasoft/virtualenv/erpcons/3.9/lib/python3.9/site-packages/django/utils/decorators.py", line 46, in _wrapper
    return bound_method(*args, **kwargs)
  File "/home/vitasoft/virtualenv/erpcons/3.9/lib/python3.9/site-packages/django/utils/decorators.py", line 134, in _wrapper_view
    response = view_func(request, *args, **kwargs)
  File "/home/vitasoft/virtualenv/erpcons/3.9/lib/python3.9/site-packages/django/contrib/admin/options.py", line 1926, in changelist_view
    cl = self.get_changelist_instance(request)
  File "/home/vitasoft/virtualenv/erpcons/3.9/lib/python3.9/site-packages/django/contrib/admin/options.py", line 836, in get_changelist_instance
    return ChangeList(
  File "/home/vitasoft/virtualenv/erpcons/3.9/lib/python3.9/site-packages/django/contrib/admin/views/main.py", line 123, in __init__
    self.get_results(request)
  File "/home/vitasoft/virtualenv/erpcons/3.9/lib/python3.9/site-packages/django/contrib/admin/views/main.py", line 279, in get_results
    result_count = paginator.count
  File "/home/vitasoft/virtualenv/erpcons/3.9/lib/python3.9/site-packages/django/utils/functional.py", line 57, in __get__
    res = instance.__dict__[self.name] = self.func(instance)
  File "/home/vitasoft/virtualenv/erpcons/3.9/lib/python3.9/site-packages/django/core/paginator.py", line 93, in count
    return c()
  File "/home/vitasoft/virtualenv/erpcons/3.9/lib/python3.9/site-packages/django/db/models/query.py", line 608, in count
    return self.query.get_count(using=self.db)
  File "/home/vitasoft/virtualenv/erpcons/3.9/lib/python3.9/site-packages/django/db/models/sql/query.py", line 557, in get_count
    return obj.get_aggregation(using, {"__count": Count("*")})["__count"]
  File "/home/vitasoft/virtualenv/erpcons/3.9/lib/python3.9/site-packages/django/db/models/sql/query.py", line 543, in get_aggregation
    result = compiler.execute_sql(SINGLE)
  File "/home/vitasoft/virtualenv/erpcons/3.9/lib/python3.9/site-packages/django/db/models/sql/compiler.py", line 1562, in execute_sql
    cursor.execute(sql, params)
  File "/home/vitasoft/virtualenv/erpcons/3.9/lib/python3.9/site-packages/django/db/backends/utils.py", line 102, in execute
    return super().execute(sql, params)
  File "/home/vitasoft/virtualenv/erpcons/3.9/lib/python3.9/site-packages/django/db/backends/utils.py", line 67, in execute
    return self._execute_with_wrappers(
  File "/home/vitasoft/virtualenv/erpcons/3.9/lib/python3.9/site-packages/django/db/backends/utils.py", line 80, in _execute_with_wrappers
    return executor(sql, params, many, context)
  File "/home/vitasoft/virtualenv/erpcons/3.9/lib/python3.9/site-packages/django/db/backends/utils.py", line 89, in _execute
    return self.cursor.execute(sql, params)
  File "/home/vitasoft/virtualenv/erpcons/3.9/lib/python3.9/site-packages/django/db/utils.py", line 91, in __exit__
    raise dj_exc_value.with_traceback(traceback) from exc_value
  File "/home/vitasoft/virtualenv/erpcons/3.9/lib/python3.9/site-packages/django/db/backends/utils.py", line 89, in _execute
    return self.cursor.execute(sql, params)
  File "/home/vitasoft/virtualenv/erpcons/3.9/lib/python3.9/site-packages/django/db/backends/mysql/base.py", line 75, in execute
    return self.cursor.execute(query, args)
  File "/home/vitasoft/virtualenv/erpcons/3.9/lib/python3.9/site-packages/pymysql/cursors.py", line 153, in execute
    result = self._query(query)
  File "/home/vitasoft/virtualenv/erpcons/3.9/lib/python3.9/site-packages/pymysql/cursors.py", line 322, in _query
    conn.query(q)
  File "/home/vitasoft/virtualenv/erpcons/3.9/lib/python3.9/site-packages/pymysql/connections.py", line 558, in query
    self._affected_rows = self._read_query_result(unbuffered=unbuffered)
  File "/home/vitasoft/virtualenv/erpcons/3.9/lib/python3.9/site-packages/pymysql/connections.py", line 822, in _read_query_result
    result.read()
  File "/home/vitasoft/virtualenv/erpcons/3.9/lib/python3.9/site-packages/pymysql/connections.py", line 1200, in read
    first_packet = self.connection._read_packet()
  File "/home/vitasoft/virtualenv/erpcons/3.9/lib/python3.9/site-packages/pymysql/connections.py", line 772, in _read_packet
    packet.raise_for_error()
  File "/home/vitasoft/virtualenv/erpcons/3.9/lib/python3.9/site-packages/pymysql/protocol.py", line 221, in raise_for_error
    err.raise_mysql_exception(self._data)
  File "/home/vitasoft/virtualenv/erpcons/3.9/lib/python3.9/site-packages/pymysql/err.py", line 143, in raise_mysql_exception
    raise errorclass(errno, errval)
django.db.utils.ProgrammingError: (1146, "Table 'vitasoft_erpcons.owner_ownerbeneficaries' doesn't exist")
Internal Server Error: /admin/loan/loanbeneficaries/
Traceback (most recent call last):
  File "/home/vitasoft/virtualenv/erpcons/3.9/lib/python3.9/site-packages/django/db/backends/utils.py", line 89, in _execute
    return self.cursor.execute(sql, params)
  File "/home/vitasoft/virtualenv/erpcons/3.9/lib/python3.9/site-packages/django/db/backends/mysql/base.py", line 75, in execute
    return self.cursor.execute(query, args)
  File "/home/vitasoft/virtualenv/erpcons/3.9/lib/python3.9/site-packages/pymysql/cursors.py", line 153, in execute
    result = self._query(query)
  File "/home/vitasoft/virtualenv/erpcons/3.9/lib/python3.9/site-packages/pymysql/cursors.py", line 322, in _query
    conn.query(q)
  File "/home/vitasoft/virtualenv/erpcons/3.9/lib/python3.9/site-packages/pymysql/connections.py", line 558, in query
    self._affected_rows = self._read_query_result(unbuffered=unbuffered)
  File "/home/vitasoft/virtualenv/erpcons/3.9/lib/python3.9/site-packages/pymysql/connections.py", line 822, in _read_query_result
    result.read()
  File "/home/vitasoft/virtualenv/erpcons/3.9/lib/python3.9/site-packages/pymysql/connections.py", line 1200, in read
    first_packet = self.connection._read_packet()
  File "/home/vitasoft/virtualenv/erpcons/3.9/lib/python3.9/site-packages/pymysql/connections.py", line 772, in _read_packet
    packet.raise_for_error()
  File "/home/vitasoft/virtualenv/erpcons/3.9/lib/python3.9/site-packages/pymysql/protocol.py", line 221, in raise_for_error
    err.raise_mysql_exception(self._data)
  File "/home/vitasoft/virtualenv/erpcons/3.9/lib/python3.9/site-packages/pymysql/err.py", line 143, in raise_mysql_exception
    raise errorclass(errno, errval)
pymysql.err.ProgrammingError: (1146, "Table 'vitasoft_erpcons.loan_loanbeneficaries' doesn't exist")

The above exception was the direct cause of the following exception:

Traceback (most recent call last):
  File "/home/vitasoft/virtualenv/erpcons/3.9/lib/python3.9/site-packages/django/core/handlers/exception.py", line 55, in inner
    response = get_response(request)
  File "/home/vitasoft/virtualenv/erpcons/3.9/lib/python3.9/site-packages/django/core/handlers/base.py", line 197, in _get_response
    response = wrapped_callback(request, *callback_args, **callback_kwargs)
  File "/home/vitasoft/virtualenv/erpcons/3.9/lib/python3.9/site-packages/django/contrib/admin/options.py", line 688, in wrapper
    return self.admin_site.admin_view(view)(*args, **kwargs)
  File "/home/vitasoft/virtualenv/erpcons/3.9/lib/python3.9/site-packages/django/utils/decorators.py", line 134, in _wrapper_view
    response = view_func(request, *args, **kwargs)
  File "/home/vitasoft/virtualenv/erpcons/3.9/lib/python3.9/site-packages/django/views/decorators/cache.py", line 62, in _wrapper_view_func
    response = view_func(request, *args, **kwargs)
  File "/home/vitasoft/virtualenv/erpcons/3.9/lib/python3.9/site-packages/django/contrib/admin/sites.py", line 242, in inner
    return view(request, *args, **kwargs)
  File "/home/vitasoft/virtualenv/erpcons/3.9/lib/python3.9/site-packages/django/utils/decorators.py", line 46, in _wrapper
    return bound_method(*args, **kwargs)
  File "/home/vitasoft/virtualenv/erpcons/3.9/lib/python3.9/site-packages/django/utils/decorators.py", line 134, in _wrapper_view
    response = view_func(request, *args, **kwargs)
  File "/home/vitasoft/virtualenv/erpcons/3.9/lib/python3.9/site-packages/django/contrib/admin/options.py", line 1926, in changelist_view
    cl = self.get_changelist_instance(request)
  File "/home/vitasoft/virtualenv/erpcons/3.9/lib/python3.9/site-packages/django/contrib/admin/options.py", line 836, in get_changelist_instance
    return ChangeList(
  File "/home/vitasoft/virtualenv/erpcons/3.9/lib/python3.9/site-packages/django/contrib/admin/views/main.py", line 123, in __init__
    self.get_results(request)
  File "/home/vitasoft/virtualenv/erpcons/3.9/lib/python3.9/site-packages/django/contrib/admin/views/main.py", line 279, in get_results
    result_count = paginator.count
  File "/home/vitasoft/virtualenv/erpcons/3.9/lib/python3.9/site-packages/django/utils/functional.py", line 57, in __get__
    res = instance.__dict__[self.name] = self.func(instance)
  File "/home/vitasoft/virtualenv/erpcons/3.9/lib/python3.9/site-packages/django/core/paginator.py", line 93, in count
    return c()
  File "/home/vitasoft/virtualenv/erpcons/3.9/lib/python3.9/site-packages/django/db/models/query.py", line 608, in count
    return self.query.get_count(using=self.db)
  File "/home/vitasoft/virtualenv/erpcons/3.9/lib/python3.9/site-packages/django/db/models/sql/query.py", line 557, in get_count
    return obj.get_aggregation(using, {"__count": Count("*")})["__count"]
  File "/home/vitasoft/virtualenv/erpcons/3.9/lib/python3.9/site-packages/django/db/models/sql/query.py", line 543, in get_aggregation
    result = compiler.execute_sql(SINGLE)
  File "/home/vitasoft/virtualenv/erpcons/3.9/lib/python3.9/site-packages/django/db/models/sql/compiler.py", line 1562, in execute_sql
    cursor.execute(sql, params)
  File "/home/vitasoft/virtualenv/erpcons/3.9/lib/python3.9/site-packages/django/db/backends/utils.py", line 102, in execute
    return super().execute(sql, params)
  File "/home/vitasoft/virtualenv/erpcons/3.9/lib/python3.9/site-packages/django/db/backends/utils.py", line 67, in execute
    return self._execute_with_wrappers(
  File "/home/vitasoft/virtualenv/erpcons/3.9/lib/python3.9/site-packages/django/db/backends/utils.py", line 80, in _execute_with_wrappers
    return executor(sql, params, many, context)
  File "/home/vitasoft/virtualenv/erpcons/3.9/lib/python3.9/site-packages/django/db/backends/utils.py", line 89, in _execute
    return self.cursor.execute(sql, params)
  File "/home/vitasoft/virtualenv/erpcons/3.9/lib/python3.9/site-packages/django/db/utils.py", line 91, in __exit__
    raise dj_exc_value.with_traceback(traceback) from exc_value
  File "/home/vitasoft/virtualenv/erpcons/3.9/lib/python3.9/site-packages/django/db/backends/utils.py", line 89, in _execute
    return self.cursor.execute(sql, params)
  File "/home/vitasoft/virtualenv/erpcons/3.9/lib/python3.9/site-packages/django/db/backends/mysql/base.py", line 75, in execute
    return self.cursor.execute(query, args)
  File "/home/vitasoft/virtualenv/erpcons/3.9/lib/python3.9/site-packages/pymysql/cursors.py", line 153, in execute
    result = self._query(query)
  File "/home/vitasoft/virtualenv/erpcons/3.9/lib/python3.9/site-packages/pymysql/cursors.py", line 322, in _query
    conn.query(q)
  File "/home/vitasoft/virtualenv/erpcons/3.9/lib/python3.9/site-packages/pymysql/connections.py", line 558, in query
    self._affected_rows = self._read_query_result(unbuffered=unbuffered)
  File "/home/vitasoft/virtualenv/erpcons/3.9/lib/python3.9/site-packages/pymysql/connections.py", line 822, in _read_query_result
    result.read()
  File "/home/vitasoft/virtualenv/erpcons/3.9/lib/python3.9/site-packages/pymysql/connections.py", line 1200, in read
    first_packet = self.connection._read_packet()
  File "/home/vitasoft/virtualenv/erpcons/3.9/lib/python3.9/site-packages/pymysql/connections.py", line 772, in _read_packet
    packet.raise_for_error()
  File "/home/vitasoft/virtualenv/erpcons/3.9/lib/python3.9/site-packages/pymysql/protocol.py", line 221, in raise_for_error
    err.raise_mysql_exception(self._data)
  File "/home/vitasoft/virtualenv/erpcons/3.9/lib/python3.9/site-packages/pymysql/err.py", line 143, in raise_mysql_exception
    raise errorclass(errno, errval)
django.db.utils.ProgrammingError: (1146, "Table 'vitasoft_erpcons.loan_loanbeneficaries' doesn't exist")
Internal Server Error: /admin/hrm/leaves/
Traceback (most recent call last):
  File "/home/vitasoft/virtualenv/erpcons/3.9/lib/python3.9/site-packages/django/db/backends/utils.py", line 89, in _execute
    return self.cursor.execute(sql, params)
  File "/home/vitasoft/virtualenv/erpcons/3.9/lib/python3.9/site-packages/django/db/backends/mysql/base.py", line 75, in execute
    return self.cursor.execute(query, args)
  File "/home/vitasoft/virtualenv/erpcons/3.9/lib/python3.9/site-packages/pymysql/cursors.py", line 153, in execute
    result = self._query(query)
  File "/home/vitasoft/virtualenv/erpcons/3.9/lib/python3.9/site-packages/pymysql/cursors.py", line 322, in _query
    conn.query(q)
  File "/home/vitasoft/virtualenv/erpcons/3.9/lib/python3.9/site-packages/pymysql/connections.py", line 558, in query
    self._affected_rows = self._read_query_result(unbuffered=unbuffered)
  File "/home/vitasoft/virtualenv/erpcons/3.9/lib/python3.9/site-packages/pymysql/connections.py", line 822, in _read_query_result
    result.read()
  File "/home/vitasoft/virtualenv/erpcons/3.9/lib/python3.9/site-packages/pymysql/connections.py", line 1200, in read
    first_packet = self.connection._read_packet()
  File "/home/vitasoft/virtualenv/erpcons/3.9/lib/python3.9/site-packages/pymysql/connections.py", line 772, in _read_packet
    packet.raise_for_error()
  File "/home/vitasoft/virtualenv/erpcons/3.9/lib/python3.9/site-packages/pymysql/protocol.py", line 221, in raise_for_error
    err.raise_mysql_exception(self._data)
  File "/home/vitasoft/virtualenv/erpcons/3.9/lib/python3.9/site-packages/pymysql/err.py", line 143, in raise_mysql_exception
    raise errorclass(errno, errval)
pymysql.err.ProgrammingError: (1146, "Table 'vitasoft_erpcons.hrm_leaves' doesn't exist")

The above exception was the direct cause of the following exception:

Traceback (most recent call last):
  File "/home/vitasoft/virtualenv/erpcons/3.9/lib/python3.9/site-packages/django/core/handlers/exception.py", line 55, in inner
    response = get_response(request)
  File "/home/vitasoft/virtualenv/erpcons/3.9/lib/python3.9/site-packages/django/core/handlers/base.py", line 197, in _get_response
    response = wrapped_callback(request, *callback_args, **callback_kwargs)
  File "/home/vitasoft/virtualenv/erpcons/3.9/lib/python3.9/site-packages/django/contrib/admin/options.py", line 688, in wrapper
    return self.admin_site.admin_view(view)(*args, **kwargs)
  File "/home/vitasoft/virtualenv/erpcons/3.9/lib/python3.9/site-packages/django/utils/decorators.py", line 134, in _wrapper_view
    response = view_func(request, *args, **kwargs)
  File "/home/vitasoft/virtualenv/erpcons/3.9/lib/python3.9/site-packages/django/views/decorators/cache.py", line 62, in _wrapper_view_func
    response = view_func(request, *args, **kwargs)
  File "/home/vitasoft/virtualenv/erpcons/3.9/lib/python3.9/site-packages/django/contrib/admin/sites.py", line 242, in inner
    return view(request, *args, **kwargs)
  File "/home/vitasoft/virtualenv/erpcons/3.9/lib/python3.9/site-packages/django/utils/decorators.py", line 46, in _wrapper
    return bound_method(*args, **kwargs)
  File "/home/vitasoft/virtualenv/erpcons/3.9/lib/python3.9/site-packages/django/utils/decorators.py", line 134, in _wrapper_view
    response = view_func(request, *args, **kwargs)
  File "/home/vitasoft/virtualenv/erpcons/3.9/lib/python3.9/site-packages/django/contrib/admin/options.py", line 1926, in changelist_view
    cl = self.get_changelist_instance(request)
  File "/home/vitasoft/virtualenv/erpcons/3.9/lib/python3.9/site-packages/django/contrib/admin/options.py", line 836, in get_changelist_instance
    return ChangeList(
  File "/home/vitasoft/virtualenv/erpcons/3.9/lib/python3.9/site-packages/django/contrib/admin/views/main.py", line 123, in __init__
    self.get_results(request)
  File "/home/vitasoft/virtualenv/erpcons/3.9/lib/python3.9/site-packages/django/contrib/admin/views/main.py", line 279, in get_results
    result_count = paginator.count
  File "/home/vitasoft/virtualenv/erpcons/3.9/lib/python3.9/site-packages/django/utils/functional.py", line 57, in __get__
    res = instance.__dict__[self.name] = self.func(instance)
  File "/home/vitasoft/virtualenv/erpcons/3.9/lib/python3.9/site-packages/django/core/paginator.py", line 93, in count
    return c()
  File "/home/vitasoft/virtualenv/erpcons/3.9/lib/python3.9/site-packages/django/db/models/query.py", line 608, in count
    return self.query.get_count(using=self.db)
  File "/home/vitasoft/virtualenv/erpcons/3.9/lib/python3.9/site-packages/django/db/models/sql/query.py", line 557, in get_count
    return obj.get_aggregation(using, {"__count": Count("*")})["__count"]
  File "/home/vitasoft/virtualenv/erpcons/3.9/lib/python3.9/site-packages/django/db/models/sql/query.py", line 543, in get_aggregation
    result = compiler.execute_sql(SINGLE)
  File "/home/vitasoft/virtualenv/erpcons/3.9/lib/python3.9/site-packages/django/db/models/sql/compiler.py", line 1562, in execute_sql
    cursor.execute(sql, params)
  File "/home/vitasoft/virtualenv/erpcons/3.9/lib/python3.9/site-packages/django/db/backends/utils.py", line 102, in execute
    return super().execute(sql, params)
  File "/home/vitasoft/virtualenv/erpcons/3.9/lib/python3.9/site-packages/django/db/backends/utils.py", line 67, in execute
    return self._execute_with_wrappers(
  File "/home/vitasoft/virtualenv/erpcons/3.9/lib/python3.9/site-packages/django/db/backends/utils.py", line 80, in _execute_with_wrappers
    return executor(sql, params, many, context)
  File "/home/vitasoft/virtualenv/erpcons/3.9/lib/python3.9/site-packages/django/db/backends/utils.py", line 89, in _execute
    return self.cursor.execute(sql, params)
  File "/home/vitasoft/virtualenv/erpcons/3.9/lib/python3.9/site-packages/django/db/utils.py", line 91, in __exit__
    raise dj_exc_value.with_traceback(traceback) from exc_value
  File "/home/vitasoft/virtualenv/erpcons/3.9/lib/python3.9/site-packages/django/db/backends/utils.py", line 89, in _execute
    return self.cursor.execute(sql, params)
  File "/home/vitasoft/virtualenv/erpcons/3.9/lib/python3.9/site-packages/django/db/backends/mysql/base.py", line 75, in execute
    return self.cursor.execute(query, args)
  File "/home/vitasoft/virtualenv/erpcons/3.9/lib/python3.9/site-packages/pymysql/cursors.py", line 153, in execute
    result = self._query(query)
  File "/home/vitasoft/virtualenv/erpcons/3.9/lib/python3.9/site-packages/pymysql/cursors.py", line 322, in _query
    conn.query(q)
  File "/home/vitasoft/virtualenv/erpcons/3.9/lib/python3.9/site-packages/pymysql/connections.py", line 558, in query
    self._affected_rows = self._read_query_result(unbuffered=unbuffered)
  File "/home/vitasoft/virtualenv/erpcons/3.9/lib/python3.9/site-packages/pymysql/connections.py", line 822, in _read_query_result
    result.read()
  File "/home/vitasoft/virtualenv/erpcons/3.9/lib/python3.9/site-packages/pymysql/connections.py", line 1200, in read
    first_packet = self.connection._read_packet()
  File "/home/vitasoft/virtualenv/erpcons/3.9/lib/python3.9/site-packages/pymysql/connections.py", line 772, in _read_packet
    packet.raise_for_error()
  File "/home/vitasoft/virtualenv/erpcons/3.9/lib/python3.9/site-packages/pymysql/protocol.py", line 221, in raise_for_error
    err.raise_mysql_exception(self._data)
  File "/home/vitasoft/virtualenv/erpcons/3.9/lib/python3.9/site-packages/pymysql/err.py", line 143, in raise_mysql_exception
    raise errorclass(errno, errval)
django.db.utils.ProgrammingError: (1146, "Table 'vitasoft_erpcons.hrm_leaves' doesn't exist")
Internal Server Error: /admin/django_rest_passwordreset/resetpasswordtoken/
Traceback (most recent call last):
  File "/home/vitasoft/virtualenv/erpcons/3.9/lib/python3.9/site-packages/django/db/backends/utils.py", line 89, in _execute
    return self.cursor.execute(sql, params)
  File "/home/vitasoft/virtualenv/erpcons/3.9/lib/python3.9/site-packages/django/db/backends/mysql/base.py", line 75, in execute
    return self.cursor.execute(query, args)
  File "/home/vitasoft/virtualenv/erpcons/3.9/lib/python3.9/site-packages/pymysql/cursors.py", line 153, in execute
    result = self._query(query)
  File "/home/vitasoft/virtualenv/erpcons/3.9/lib/python3.9/site-packages/pymysql/cursors.py", line 322, in _query
    conn.query(q)
  File "/home/vitasoft/virtualenv/erpcons/3.9/lib/python3.9/site-packages/pymysql/connections.py", line 558, in query
    self._affected_rows = self._read_query_result(unbuffered=unbuffered)
  File "/home/vitasoft/virtualenv/erpcons/3.9/lib/python3.9/site-packages/pymysql/connections.py", line 822, in _read_query_result
    result.read()
  File "/home/vitasoft/virtualenv/erpcons/3.9/lib/python3.9/site-packages/pymysql/connections.py", line 1200, in read
    first_packet = self.connection._read_packet()
  File "/home/vitasoft/virtualenv/erpcons/3.9/lib/python3.9/site-packages/pymysql/connections.py", line 772, in _read_packet
    packet.raise_for_error()
  File "/home/vitasoft/virtualenv/erpcons/3.9/lib/python3.9/site-packages/pymysql/protocol.py", line 221, in raise_for_error
    err.raise_mysql_exception(self._data)
  File "/home/vitasoft/virtualenv/erpcons/3.9/lib/python3.9/site-packages/pymysql/err.py", line 143, in raise_mysql_exception
    raise errorclass(errno, errval)
pymysql.err.ProgrammingError: (1146, "Table 'vitasoft_erpcons.django_rest_passwordreset_resetpasswordtoken' doesn't exist")

The above exception was the direct cause of the following exception:

Traceback (most recent call last):
  File "/home/vitasoft/virtualenv/erpcons/3.9/lib/python3.9/site-packages/django/core/handlers/exception.py", line 55, in inner
    response = get_response(request)
  File "/home/vitasoft/virtualenv/erpcons/3.9/lib/python3.9/site-packages/django/core/handlers/base.py", line 197, in _get_response
    response = wrapped_callback(request, *callback_args, **callback_kwargs)
  File "/home/vitasoft/virtualenv/erpcons/3.9/lib/python3.9/site-packages/django/contrib/admin/options.py", line 688, in wrapper
    return self.admin_site.admin_view(view)(*args, **kwargs)
  File "/home/vitasoft/virtualenv/erpcons/3.9/lib/python3.9/site-packages/django/utils/decorators.py", line 134, in _wrapper_view
    response = view_func(request, *args, **kwargs)
  File "/home/vitasoft/virtualenv/erpcons/3.9/lib/python3.9/site-packages/django/views/decorators/cache.py", line 62, in _wrapper_view_func
    response = view_func(request, *args, **kwargs)
  File "/home/vitasoft/virtualenv/erpcons/3.9/lib/python3.9/site-packages/django/contrib/admin/sites.py", line 242, in inner
    return view(request, *args, **kwargs)
  File "/home/vitasoft/virtualenv/erpcons/3.9/lib/python3.9/site-packages/django/utils/decorators.py", line 46, in _wrapper
    return bound_method(*args, **kwargs)
  File "/home/vitasoft/virtualenv/erpcons/3.9/lib/python3.9/site-packages/django/utils/decorators.py", line 134, in _wrapper_view
    response = view_func(request, *args, **kwargs)
  File "/home/vitasoft/virtualenv/erpcons/3.9/lib/python3.9/site-packages/django/contrib/admin/options.py", line 1926, in changelist_view
    cl = self.get_changelist_instance(request)
  File "/home/vitasoft/virtualenv/erpcons/3.9/lib/python3.9/site-packages/django/contrib/admin/options.py", line 836, in get_changelist_instance
    return ChangeList(
  File "/home/vitasoft/virtualenv/erpcons/3.9/lib/python3.9/site-packages/django/contrib/admin/views/main.py", line 123, in __init__
    self.get_results(request)
  File "/home/vitasoft/virtualenv/erpcons/3.9/lib/python3.9/site-packages/django/contrib/admin/views/main.py", line 279, in get_results
    result_count = paginator.count
  File "/home/vitasoft/virtualenv/erpcons/3.9/lib/python3.9/site-packages/django/utils/functional.py", line 57, in __get__
    res = instance.__dict__[self.name] = self.func(instance)
  File "/home/vitasoft/virtualenv/erpcons/3.9/lib/python3.9/site-packages/django/core/paginator.py", line 93, in count
    return c()
  File "/home/vitasoft/virtualenv/erpcons/3.9/lib/python3.9/site-packages/django/db/models/query.py", line 608, in count
    return self.query.get_count(using=self.db)
  File "/home/vitasoft/virtualenv/erpcons/3.9/lib/python3.9/site-packages/django/db/models/sql/query.py", line 557, in get_count
    return obj.get_aggregation(using, {"__count": Count("*")})["__count"]
  File "/home/vitasoft/virtualenv/erpcons/3.9/lib/python3.9/site-packages/django/db/models/sql/query.py", line 543, in get_aggregation
    result = compiler.execute_sql(SINGLE)
  File "/home/vitasoft/virtualenv/erpcons/3.9/lib/python3.9/site-packages/django/db/models/sql/compiler.py", line 1562, in execute_sql
    cursor.execute(sql, params)
  File "/home/vitasoft/virtualenv/erpcons/3.9/lib/python3.9/site-packages/django/db/backends/utils.py", line 102, in execute
    return super().execute(sql, params)
  File "/home/vitasoft/virtualenv/erpcons/3.9/lib/python3.9/site-packages/django/db/backends/utils.py", line 67, in execute
    return self._execute_with_wrappers(
  File "/home/vitasoft/virtualenv/erpcons/3.9/lib/python3.9/site-packages/django/db/backends/utils.py", line 80, in _execute_with_wrappers
    return executor(sql, params, many, context)
  File "/home/vitasoft/virtualenv/erpcons/3.9/lib/python3.9/site-packages/django/db/backends/utils.py", line 89, in _execute
    return self.cursor.execute(sql, params)
  File "/home/vitasoft/virtualenv/erpcons/3.9/lib/python3.9/site-packages/django/db/utils.py", line 91, in __exit__
    raise dj_exc_value.with_traceback(traceback) from exc_value
  File "/home/vitasoft/virtualenv/erpcons/3.9/lib/python3.9/site-packages/django/db/backends/utils.py", line 89, in _execute
    return self.cursor.execute(sql, params)
  File "/home/vitasoft/virtualenv/erpcons/3.9/lib/python3.9/site-packages/django/db/backends/mysql/base.py", line 75, in execute
    return self.cursor.execute(query, args)
  File "/home/vitasoft/virtualenv/erpcons/3.9/lib/python3.9/site-packages/pymysql/cursors.py", line 153, in execute
    result = self._query(query)
  File "/home/vitasoft/virtualenv/erpcons/3.9/lib/python3.9/site-packages/pymysql/cursors.py", line 322, in _query
    conn.query(q)
  File "/home/vitasoft/virtualenv/erpcons/3.9/lib/python3.9/site-packages/pymysql/connections.py", line 558, in query
    self._affected_rows = self._read_query_result(unbuffered=unbuffered)
  File "/home/vitasoft/virtualenv/erpcons/3.9/lib/python3.9/site-packages/pymysql/connections.py", line 822, in _read_query_result
    result.read()
  File "/home/vitasoft/virtualenv/erpcons/3.9/lib/python3.9/site-packages/pymysql/connections.py", line 1200, in read
    first_packet = self.connection._read_packet()
  File "/home/vitasoft/virtualenv/erpcons/3.9/lib/python3.9/site-packages/pymysql/connections.py", line 772, in _read_packet
    packet.raise_for_error()
  File "/home/vitasoft/virtualenv/erpcons/3.9/lib/python3.9/site-packages/pymysql/protocol.py", line 221, in raise_for_error
    err.raise_mysql_exception(self._data)
  File "/home/vitasoft/virtualenv/erpcons/3.9/lib/python3.9/site-packages/pymysql/err.py", line 143, in raise_mysql_exception
    raise errorclass(errno, errval)
django.db.utils.ProgrammingError: (1146, "Table 'vitasoft_erpcons.django_rest_passwordreset_resetpasswordtoken' doesn't exist")
Not Found: //loan-beneficaries/
Internal Server Error: /loan-beneficaries/
Traceback (most recent call last):
  File "/home/vitasoft/virtualenv/erpcons/3.9/lib/python3.9/site-packages/django/core/handlers/exception.py", line 55, in inner
    response = get_response(request)
  File "/home/vitasoft/virtualenv/erpcons/3.9/lib/python3.9/site-packages/django/core/handlers/base.py", line 197, in _get_response
    response = wrapped_callback(request, *callback_args, **callback_kwargs)
  File "/home/vitasoft/virtualenv/erpcons/3.9/lib/python3.9/site-packages/django/views/decorators/csrf.py", line 56, in wrapper_view
    return view_func(*args, **kwargs)
  File "/home/vitasoft/virtualenv/erpcons/3.9/lib/python3.9/site-packages/rest_framework/viewsets.py", line 125, in view
    return self.dispatch(request, *args, **kwargs)
  File "/home/vitasoft/virtualenv/erpcons/3.9/lib/python3.9/site-packages/rest_framework/views.py", line 509, in dispatch
    response = self.handle_exception(exc)
  File "/home/vitasoft/virtualenv/erpcons/3.9/lib/python3.9/site-packages/rest_framework/views.py", line 469, in handle_exception
    self.raise_uncaught_exception(exc)
  File "/home/vitasoft/virtualenv/erpcons/3.9/lib/python3.9/site-packages/rest_framework/views.py", line 480, in raise_uncaught_exception
    raise exc
  File "/home/vitasoft/virtualenv/erpcons/3.9/lib/python3.9/site-packages/rest_framework/views.py", line 506, in dispatch
    response = handler(request, *args, **kwargs)
  File "/home/vitasoft/erpcons/loan/views.py", line 74, in create
    role= Beneficaries.objects.get(id=phone_number['role']),
  File "/home/vitasoft/virtualenv/erpcons/3.9/lib/python3.9/site-packages/django/db/models/manager.py", line 87, in manager_method
    return getattr(self.get_queryset(), name)(*args, **kwargs)
  File "/home/vitasoft/virtualenv/erpcons/3.9/lib/python3.9/site-packages/django/db/models/query.py", line 637, in get
    raise self.model.DoesNotExist(
globalapp2.models.Beneficaries.DoesNotExist: Beneficaries matching query does not exist.
{'name': 'Senario', 'relation': None, 'phone_number': '0179741903', 'status': True, 'created_at': '2023-08-31T17:51:14.481804Z', 'is_deleted': False, 'role': 3, 'ben_id': 1}
<class 'int'>
Internal Server Error: /loan-beneficaries/
Traceback (most recent call last):
  File "/home/vitasoft/virtualenv/erpcons/3.9/lib/python3.9/site-packages/django/core/handlers/exception.py", line 55, in inner
    response = get_response(request)
  File "/home/vitasoft/virtualenv/erpcons/3.9/lib/python3.9/site-packages/django/core/handlers/base.py", line 197, in _get_response
    response = wrapped_callback(request, *callback_args, **callback_kwargs)
  File "/home/vitasoft/virtualenv/erpcons/3.9/lib/python3.9/site-packages/django/views/decorators/csrf.py", line 56, in wrapper_view
    return view_func(*args, **kwargs)
  File "/home/vitasoft/virtualenv/erpcons/3.9/lib/python3.9/site-packages/rest_framework/viewsets.py", line 125, in view
    return self.dispatch(request, *args, **kwargs)
  File "/home/vitasoft/virtualenv/erpcons/3.9/lib/python3.9/site-packages/rest_framework/views.py", line 509, in dispatch
    response = self.handle_exception(exc)
  File "/home/vitasoft/virtualenv/erpcons/3.9/lib/python3.9/site-packages/rest_framework/views.py", line 469, in handle_exception
    self.raise_uncaught_exception(exc)
  File "/home/vitasoft/virtualenv/erpcons/3.9/lib/python3.9/site-packages/rest_framework/views.py", line 480, in raise_uncaught_exception
    raise exc
  File "/home/vitasoft/virtualenv/erpcons/3.9/lib/python3.9/site-packages/rest_framework/views.py", line 506, in dispatch
    response = handler(request, *args, **kwargs)
  File "/home/vitasoft/erpcons/loan/views.py", line 74, in create
    role= Beneficaries.objects.get(id=phone_number['role']),
  File "/home/vitasoft/virtualenv/erpcons/3.9/lib/python3.9/site-packages/django/db/models/manager.py", line 87, in manager_method
    return getattr(self.get_queryset(), name)(*args, **kwargs)
  File "/home/vitasoft/virtualenv/erpcons/3.9/lib/python3.9/site-packages/django/db/models/query.py", line 637, in get
    raise self.model.DoesNotExist(
globalapp2.models.Beneficaries.DoesNotExist: Beneficaries matching query does not exist.
{'name': 'Senario', 'relation': None, 'phone_number': '0179741903', 'status': True, 'created_at': '2023-08-31T17:51:14.481804Z', 'is_deleted': False, 'role': 3, 'ben_id': 1}
<class 'int'>
admin@gmail.com
Internal Server Error: /loan-beneficaries/
Traceback (most recent call last):
  File "/home/vitasoft/virtualenv/erpcons/3.9/lib/python3.9/site-packages/django/core/handlers/exception.py", line 55, in inner
    response = get_response(request)
  File "/home/vitasoft/virtualenv/erpcons/3.9/lib/python3.9/site-packages/django/core/handlers/base.py", line 197, in _get_response
    response = wrapped_callback(request, *callback_args, **callback_kwargs)
  File "/home/vitasoft/virtualenv/erpcons/3.9/lib/python3.9/site-packages/django/views/decorators/csrf.py", line 56, in wrapper_view
    return view_func(*args, **kwargs)
  File "/home/vitasoft/virtualenv/erpcons/3.9/lib/python3.9/site-packages/rest_framework/viewsets.py", line 125, in view
    return self.dispatch(request, *args, **kwargs)
  File "/home/vitasoft/virtualenv/erpcons/3.9/lib/python3.9/site-packages/rest_framework/views.py", line 509, in dispatch
    response = self.handle_exception(exc)
  File "/home/vitasoft/virtualenv/erpcons/3.9/lib/python3.9/site-packages/rest_framework/views.py", line 469, in handle_exception
    self.raise_uncaught_exception(exc)
  File "/home/vitasoft/virtualenv/erpcons/3.9/lib/python3.9/site-packages/rest_framework/views.py", line 480, in raise_uncaught_exception
    raise exc
  File "/home/vitasoft/virtualenv/erpcons/3.9/lib/python3.9/site-packages/rest_framework/views.py", line 506, in dispatch
    response = handler(request, *args, **kwargs)
  File "/home/vitasoft/erpcons/loan/views.py", line 74, in create
    role= Beneficaries.objects.get(id=phone_number['role']),
  File "/home/vitasoft/virtualenv/erpcons/3.9/lib/python3.9/site-packages/django/db/models/manager.py", line 87, in manager_method
    return getattr(self.get_queryset(), name)(*args, **kwargs)
  File "/home/vitasoft/virtualenv/erpcons/3.9/lib/python3.9/site-packages/django/db/models/query.py", line 637, in get
    raise self.model.DoesNotExist(
globalapp2.models.Beneficaries.DoesNotExist: Beneficaries matching query does not exist.
{'name': 'Senario', 'relation': None, 'phone_number': '0179741903', 'status': True, 'created_at': '2023-08-31T17:51:14.481804Z', 'is_deleted': False, 'role': 13, 'ben_id': 1}
<class 'int'>
Method Not Allowed: /login/
